Workbook
Name Slicer_Mandatory_BY_Version: #N/A
Name Slicer_Mandatory_BY_Version1: #N/A

Sheet Sheet2
A1: Wave1 - Simple Pages
A2: Wave2 - Modarate Pages
A3: Wave3 - Complex Pages

Sheet Sheet1

Sheet Additional comment MFG & QA
A1: Product | B1: Module | C1: Comment | D1: Total Features
A2: Manufacturing | B2: Manufacturing | C2: Included in Mfg Wave | D2: 38
A3: Manufacturing | B3: Smart Operations | C3: Excluded from Mfg Wave, since this is an entirely new offering | D3: 36
A4: Manufacturing | B4: Kanban | C4: Included in Mfg Wave | D4: 3
A5: Manufacturing | B5: Flow Manufacturing | C5: Excluded from Mfg Wave, since this is an entirely new offering | D5: 7
A6: Manufacturing | B6: Supply Chain Orchestration | C6: Included in Mfg Wave | D6: 5
A7: Quality Management | B7: Quality Inspection Management | C7: Included in QA Wave | D7: 11
C10: Product | D10: Manufacturing
C11: Module | D11: Manufacturing, Kanban, Supply Chain Orchestration
C12: Row Labels | D12: Count of Redwood Features
C13: Wave1 - Simple Pages | D13: 20
C14: Wave2 - Modarate Pages | D14: 14
C15: Wave3 - Complex Pages | D15: 12
C16: Grand Total | D16: 46
C23: Product | D23: Quality Management
C24: Module | D24: Quality Management
C25: Row Labels | D25: Count of Redwood Features
C26: Wave1 - Simple Pages | D26: 11
C27: Grand Total | D27: 11

Sheet Feature By Release
A3: Count of S.no | B3: Column Labels
A4: Row Labels | B4: 22B | C4: 22C | D4: 22D | E4: 23A | F4: 23B | G4: 23C | H4: 23D | I4: 24A | J4: 24B | K4: 24C | L4: 24D | M4: 25A | N4: 25B | O4: 25C | P4: 25D | Q4: 26A | R4: Grand Total
A5: Inventory Management | I5: 1 | J5: 2 | K5: 7 | L5: 17 | M5: 43 | N5: 77 | O5: 31 | P5: 34 | Q5: 32 | R5: 244
A6: Maintenance | M6: 4 | N6: 5 | O6: 14 | P6: 8 | Q6: 14 | R6: 45
A7: Manufacturing | J7: 3 | K7: 7 | L7: 14 | M7: 24 | N7: 19 | O7: 11 | P7: 6 | Q7: 14 | R7: 98
A8: Order Management | F8: 1 | G8: 3 | K8: 2 | L8: 8 | M8: 12 | N8: 19 | O8: 12 | P8: 16 | Q8: 21 | R8: 94
A9: Procurement | B9: 1 | C9: 2 | D9: 5 | E9: 4 | F9: 5 | G9: 4 | H9: 7 | J9: 7 | K9: 9 | L9: 17 | M9: 25 | N9: 40 | O9: 66 | P9: 61 | Q9: 68 | R9: 321
A10: Product Hub | J10: 6 | K10: 1 | L10: 8 | N10: 3 | R10: 18
A11: Product Lifecycle Management | J11: 1 | K11: 1 | P11: 12 | Q11: 20 | R11: 34
A12: Quality Management | J12: 1 | K12: 3 | M12: 1 | N12: 2 | O12: 1 | P12: 3 | Q12: 1 | R12: 12
A13: SCM Common Components | K13: 1 | N13: 1 | P13: 3 | R13: 5
A14: Supply Chain Collaboration | J14: 4 | K14: 3 | L14: 4 | N14: 1 | R14: 12
A15: Supply Chain Orchestration | K15: 3 | M15: 1 | N15: 1 | O15: 6 | P15: 18 | Q15: 9 | R15: 38
A16: Supply Chain Planning | J16: 7 | K16: 14 | L16: 14 | M16: 6 | N16: 43 | O16: 42 | P16: 48 | Q16: 64 | R16: 238
A17: Grand Total | B17: 1 | C17: 2 | D17: 5 | E17: 4 | F17: 6 | G17: 7 | H17: 7 | I17: 1 | J17: 31 | K17: 51 | L17: 82 | M17: 116 | N17: 211 | O17: 183 | P17: 209 | Q17: 243 | R17: 1159

Sheet Feature by Mandatory
A3: Count of S.no | B3: Column Labels
A4: Row Labels | B4: 25A | C4: 25B | D4: 25C | E4: 25D | F4: 26A | G4: 26B | H4: 26C | I4: 26D | J4: 27A | K4: (blank) | L4: Grand Total
A5: Inventory Management | B5: 2 | C5: 92 | D5: 45 | E5: 47 | F5: 30 | G5: 12 | I5: 1 | J5: 15 | L5: 244
A6: Maintenance | F6: 6 | G6: 1 | H6: 31 | I6: 7 | L6: 45
A7: Manufacturing | B7: 2 | C7: 10 | D7: 4 | E7: 12 | F7: 66 | G7: 1 | H7: 3 | L7: 98
A8: Order Management | B8: 1 | C8: 3 | D8: 5 | E8: 5 | F8: 10 | G8: 67 | J8: 3 | L8: 94
A9: Procurement | C9: 5 | D9: 78 | E9: 37 | F9: 76 | G9: 112 | H9: 3 | J9: 10 | L9: 321
A10: Product Hub | C10: 3 | D10: 2 | E10: 4 | F10: 4 | G10: 2 | H10: 3 | L10: 18
A11: Product Lifecycle Management | E11: 7 | F11: 6 | G11: 6 | I11: 13 | K11: 2 | L11: 34
A12: Quality Management | C12: 1 | E12: 6 | F12: 3 | G12: 2 | L12: 12
A13: SCM Common Components | D13: 1 | E13: 2 | F13: 1 | H13: 1 | L13: 5
A14: Supply Chain Collaboration | C14: 3 | E14: 1 | F14: 3 | G14: 2 | H14: 3 | L14: 12
A15: Supply Chain Orchestration | D15: 5 | E15: 9 | F15: 8 | G15: 12 | I15: 1 | J15: 3 | L15: 38
A16: Supply Chain Planning | F16: 1 | G16: 237 | L16: 238
A17: Grand Total | B17: 5 | C17: 117 | D17: 140 | E17: 130 | F17: 214 | G17: 454 | H17: 44 | I17: 22 | J17: 31 | K17: 2 | L17: 1159

Sheet Feature By Wave
A3: Count of S.no | B3: Column Labels
A4: Row Labels | B4: Wave1 - Simple Pages | C4: Wave2 - Modarate Pages | D4: Wave3 - Complex Pages | E4: (blank) | F4: Grand Total
A5: Inventory Management | B5: 118 | C5: 108 | D5: 18 | F5: 244
A6: Maintenance | B6: 17 | C6: 16 | D6: 12 | F6: 45
A7: Manufacturing | B7: 15 | C7: 52 | D7: 31 | F7: 98
A8: Order Management | B8: 32 | C8: 34 | D8: 28 | F8: 94
A9: Procurement | B9: 216 | C9: 97 | D9: 8 | F9: 321
A10: Product Hub | B10: 9 | C10: 7 | D10: 2 | F10: 18
A11: Product Lifecycle Management | B11: 13 | C11: 9 | D11: 11 | E11: 1 | F11: 34
A12: Quality Management | B12: 12 | F12: 12
A13: SCM Common Components | B13: 2 | C13: 3 | F13: 5
A14: Supply Chain Collaboration | B14: 10 | C14: 1 | D14: 1 | F14: 12
A15: Supply Chain Orchestration | B15: 19 | C15: 16 | D15: 3 | F15: 38
A16: Supply Chain Planning | B16: 77 | C16: 119 | D16: 42 | F16: 238
A17: Grand Total | B17: 540 | C17: 462 | D17: 156 | E17: 1 | F17: 1159

Sheet 1.11 - Final Features List
A1: S.no | B1: Product | C1: Module | D1: Feature Names | E1: Update Version | F1: Mandate Version | G1: Wave | H1: CSS Mandate Version | I1: Privilage Name | J1: Profile Options Value | K1: Additional Info | L1: Action Required | M1: Availability of PPT | N1: SME | O1: UI Page Names | P1: Remarks
A2: 1 | B2: Inventory Management | C2: Mobile Inventory | D2: Redwood: Create an Interorganization Transfer Using a Mobile Device | E2: 24D | F2: 25B | G2: Wave1 - Simple Pages | H2: 26B | I2: Create Interorganization Transfer Using Responsive Inventory Duty (ORA_INV_CREATE_INTERORG_TRANSFER_PWA_DUTY). | L2: Role Setup | M2: Y | N2: G, Pravalika | O2: Inventory Management (Mobile)
A3: 2 | B3: Inventory Management | C3: Mobile Inventory | D3: Redwood: View the Inventory Management (New) Tile as Inventory Management (Mobile) | E3: 24D | F3: 25B | G3: Wave1 - Simple Pages | H3: 26B | L3: Auto Enabled | N3: G, Pravalika | O3: Inventory Management (Mobile)
A4: 3 | B4: Inventory Management | C4: Mobile Inventory | D4: Redwood: Inspect Received Goods Using a Mobile Device | E4: 24D | F4: 25B | G4: Wave1 - Simple Pages | H4: 26B | I4: New: Inspect goods using the responsive receiving application (ORA_RCV_INSPECT_GOODS_PWA_DUTY) | J4: Manage Inventory Profile Options > ORA_INV_MOBILE_INVENTORY_MANAGEMENT_REDWOOD_ENABLED = Yes | K4: 1. Activate Sandbox to enable the Inventory Management (New) 2. Run the "ESS job to create index definition and perform Initial Ingest to OSCS" Refer: https://docs.oracle.com/en/cloud/saas/readiness/scm/24b/inv24b/24B-inventory-wn-f31373.htm | L4: Profile Option | N4: G, Pravalika | O4: Inventory Management (Mobile)
A5: 4 | B5: Inventory Management | C5: Mobile Inventory | D5: Redwood: View Lot Attributes in Mobile Inventory Transactions | E5: 24D | F5: 25B | G5: Wave1 - Simple Pages | H5: 26B | L5: Auto Enabled | N5: G, Pravalika | O5: Inventory Management (Mobile)
A6: 5 | B6: Inventory Management | C6: Cost Management | D6: Redwood: View Rollup Costs Using a New User Experience | E6: 25A | F6: 25B | G6: Wave1 - Simple Pages | H6: 26A | I6: Users who are assigned a configured job role that contains the following privilege can access this feature: View Rolled Up Costs (CST_REVIEW_ROLLEDUP_COSTS) | J6: On the Manage Administrator Profile Values page, search for and select the ORA_CST_VIEW_ROLLEDUP_COSTS_REDWOOD_ENABLED profile option code. In the Profile Values section, set the Site level to Yes. The default value is No. Click Save and Close. Changes in the profile value will affect users the next time they sign in. Yes = enables the feature No = disables the feature | L6: Role Setup+Profile option | M6: Y | N6: Krishnan, Karthikeyan | O6: Cost Accounting Work Area
A7: 6 | B7: Inventory Management | C7: Cost Management | D7: Redwood: Create and Update Cost Scenarios Using a New User Experience | E7: 25A | F7: 25B | G7: Wave2 - Modarate Pages | H7: 26A | I7: Users who are assigned a configured job role that contains the following privilege can access this feature: Manage Cost Planning Scenario Definition (CST_MANAGE_SCENARIO) | J7: On the Manage Administrator Profile Values page, search for and select the ORA_CST_PLANNING_SCENARIOS_REDWOOD_ENABLED profile option code. In the Profile Values section, set the Site level to Yes. The default value is No. Click Save and Close. Changes in the profile value will affect users the next time they sign in. Yes = enables the feature No = disables the feature | L7: Role Setup+Profile option | M7: Y | N7: Krishnan, Karthikeyan | O7: Cost Accounting Work Area
A8: 7 | B8: Inventory Management | C8: Cost Management | D8: Redwood: Review Standard Costs Import Exceptions Using a New User Experience | E8: 25A | F8: 25B | G8: Wave1 - Simple Pages | H8: 26A | I8: Users who are assigned a configured job role that contains the following privilege can access this feature: Estimate Costs (CST_ESTIMATE_COSTS) | J8: On the Manage Administrator Profile Values page, search for and select the ORA_CST_STD_COST_IMPORT_EXCEPTIONS_REDWOOD_ENABLED profile option code. In the Profile Values section, set the Site level to Yes. The default value is No. Click Save and Close. Changes in the profile value will affect users the next time they sign in. Yes = enables the feature No = disables the feature | L8: Role Setup+Profile option | M8: Y | N8: Krishnan, Karthikeyan | O8: Cost Accounting Work Area
A9: 8 | B9: Inventory Management | C9: Receiving | D9: Redwood: Manage Inbound Shipments and Create ASN or ASBN Using a Redwood Page | E9: 24D | F9: 25C | G9: Wave1 - Simple Pages | H9: 26A | I9: 1. Manage Inbound Shipment Using Responsive Receiving (RCV_MANAGE_INBOUND_SHIPMENT_PWA) 2. Manage Inbound Shipment as Supplier Using Responsive Receiving (RCV_MANAGE_INBOUND_SHIPMENT_AS_SUPPLIER_PWA) 3. Create Advance Shipment Notice Using Responsive Receiving (RCV_CREATE_ADVANCE_SHIPMENT_NOTICE_PWA) 4. Create Advance Shipment Notice as Supplier Using Responsive Receiving (RCV_CREATE_ADVANCE_SHIPMENT_NOTICE_AS_SUPPLIER_PWA) | J9: Manage Receiving Profile Options > 1. ORA_RCV_INBOUND_SHIPMENTS_REDWOOD_ENABLED = Yes 2. ORA_RCV_ADVANCE_SHIPMENT_NOTICE_REDWOOD_ENABLED = Yes 3. ORA_RCV_INBOUND_SHIPMENTS_SUPPLIER_PORTAL_REDWOOD_ENABLED = Yes 4. ORA_RCV_ADVANCE_SHIPMENT_NOTICE_SUPPLIER_PORTAL_REDWOOD_ENABLED = Yes | K9: 1. Activate Sandbox to enable the Inventory Management (New) 2. Run the "ESS job to create index definition and perform Initial Ingest to OSCS" Refer: https://docs.oracle.com/en/cloud/saas/readiness/scm/24b/inv24b/24B-inventory-wn-f31373.htm | L9: Profile Option | M9: Y | N9: G, Pravalika | O9: Receipts
A10: 9 | B10: Inventory Management | C10: Receiving | D10: Redwood: View Receipts and Receipt Returns in Supplier Portal Using a Redwood Page | E10: 24D | F10: 25C | G10: Wave1 - Simple Pages | H10: 26A | I10: View Receiving Receipt and Receipt Return as Supplier (RCV_VIEW_RECEIVING_RECEIPT_AND_RECEIPT_RETURN_AS_SUPPLIER_PRIV) | J10: Manage Receiving Profile Options task > ORA_RCV_RECEIPTS_RETURNS_SUPPLIER_PORTAL_REDWOOD_ENABLED = Yes | L10: Profile Option | M10: Y | N10: G, Pravalika | O10: Supplier Portal
A11: 10 | B11: Inventory Management | C11: Cost Management | D11: Create and Edit Overhead Rates Using Redwood Pages | E11: 24C | F11: 26B | G11: Wave2 - Modarate Pages | H11: 26A | I11: Users who are assigned a configured job role that contains the following privilege can access this feature: Manage Resource and Overhead Rate Plans (CST_MANAGE_RATE_PLANS) | J11: On the Manage Administrator Profile Values page, search for and select the ORA_CST_RESOURCE_RATES_REDWOOD_ENABLED profile option code. In the Profile Values section, set the Site level to Yes. The default value is No. Yes = enables the feature No = disables the feature | L11: Role Setup+Profile option | N11: Krishnan, Karthikeyan | O11: Overhead Rates
A12: 11 | B12: Inventory Management | C12: Fiscal Document Capture | D12: Manage Tolerances Using the Redwood Experience | E12: 24C | F12: 26B | G12: Wave2 - Modarate Pages | H12: 26B | I12: Set Up Fiscal Document Tolerances (CMF_FISCAL_DOC_TOLERANCES) Manage Fiscal Document Tolerances by Web Service (CMF_FISCAL_DOC_TOLERANCE_WEB_SERVICE) | J12: On the Manage Administrator Profile Values page, enable the new ORA_CMF_TOLERANCE_RULES_REDWOOD_ENABLED profile option at Site or Product or User level. Select Yes for the Redwood page for Fiscal Document Tolerance Rules Enabled option. | L12: Role Setup+Profile option | N12: G, Pravalika | O12: Fiscal Document Tolerance Rules
A13: 12 | B13: Supply Chain Orchestration | C13: Supply Chain Orchestration | D13: Manage Documentation and Accounting Rule in Redwood Pages | E13: 24C | F13: 26B | G13: Wave1 - Simple Pages | H13: 26D | I13: Maintain Documentation and Accounting Rules (FOS_MAINTAIN_TRADE_AND_ACCOUNTING_RULES) Manage Documentation and Accounting Rules (FOS_MANAGE_TRADE_AND_ACCOUNTING_RULES) View Documentation and Accounting Rules (FOS_VIEW_TRADE_AND_ACCOUNTING_RULES) | J13: ORA_FOS_TRADE_ACCOUNTING_RULES_REDWOOD_ENABLED | L13: Role Setup+Profile option | M13: Y | N13: Sumalatha, A | O13: Documentation and Accounting Rules
A14: 13 | B14: Supply Chain Orchestration | C14: Supply Chain Orchestration | D14: Manage Transfer Pricing Rule in Redwood Pages | E14: 24C | F14: 26B | G14: Wave1 - Simple Pages | H14: 26D | I14: Maintain Transfer Pricing Rules (FOS_MAINTAIN_TRANSFER_PRICING_RULES) Manage Transfer Pricing Rules (FOS_MANAGE_TRANSFER_PRICING_RULES) View Transfer Pricing Rules (FOS_VIEW_TRANSFER_PRICING_RULES) | J14: ORA_FOS_TRANSFER_PRICING_RULES_REDWOOD_ENABLED | L14: Role Setup+Profile option | M14: Y | N14: Sumalatha, A | O14: Financial Orchestration Work Area
A15: 14 | B15: Inventory Management | C15: Cost Management | D15: Create and Update Resource Rates Using Redwood Pages | E15: 24B | F15: 26B | G15: Wave2 - Modarate Pages | H15: 26A | I15: Users who are assigned a configured job role that contains the following privilege can access this feature: Manage Resource and Overhead Rate Plans (CST_MANAGE_RATE_PLANS) | J15: On the Manage Administrator Profile Values page, search for and select the ORA_CST_RESOURCE_RATES_REDWOOD_ENABLED profile option code. In the Profile Values section, set the Site level to Yes. The default value is No. Yes = enables the feature No = disables the feature | L15: Role Setup+Profile option | N15: Krishnan, Karthikeyan | O15: Resource Rates
A16: 15 | B16: Inventory Management | C16: Cost Management | D16: Redwood: View Scenario Exceptions Using a New User Experience | E16: 25A | F16: 25B | G16: Wave1 - Simple Pages | H16: 26A | I16: Users who are assigned a configured job role that contains the following privilege can access this feature: View Scenario Exceptions (CST_MANAGE_SCENRIO_EXCEPTIONS) | J16: On the Manage Administrator Profile Values page, search for and select the ORA_CST_SCENARIO_EXCEPTIONS_REDWOOD_ENABLED profile option code. In the Profile Values section, set the Site level to Yes. The default value is No. Click Save and Close. Changes in the profile value will affect users the next time they sign in. Yes = enables the feature No = disables the feature | L16: Role Setup+Profile option | M16: Y | N16: Krishnan, Karthikeyan | O16: Cost Accounting Work Area
A17: 16 | B17: Manufacturing | C17: Manufacturing | D17: Search for, Create, and Edit a Standard Item Work Definition Using the Redwood User Experience | E17: 24B | F17: 26B | G17: Wave1 - Simple Pages | H17: 26A | J17: ORA_WIS_WORK_DEFINITIONS_REDWOOD_ENABLED | L17: Role Setup+Profile option | M17: Y | N17: Muthu Kumar Madhavan | O17: Manage Work Definitions Page
A18: 17 | B18: Order Management | C18: Channel Revenue Management | D18: Redwood: Define Product Eligibility Based on Item Categories for Customer Rebate Programs | E18: 24D | F18: 25A | G18: Wave3 - Complex Pages | H18: 26C | I18: Manage Customer Programs (CJM_MANAGE_CUSTOMER_PROGRAMS_PRIV) | K18: Use the Opt In UI to enable this feature. | L18: OPT IN+Role Setup | N18: Arepally, Susmitha | O18: Customer Programs UI (Customer rebate programs)
A19: 18 | B19: Order Management | C19: Channel Revenue Management | D19: Redwood: Exclude Multiple Items or Item Categories in Product Eligibility Rules | E19: 24D | F19: 25C | G19: Wave3 - Complex Pages | H19: 26C | I19: Manage Customer Programs (CJM_MANAGE_CUSTOMER_PROGRAMS_PRIV) | K19: Use the Opt In UI to enable this feature. | L19: OPT IN+Role Setup | N19: Arepally, Susmitha | O19: Customer Programs UI (Customer rebate programs and Customer volume programs).
A20: 19 | B20: Order Management | C20: Channel Revenue Management | D20: Redwood: Manage Manual Accrual Adjustments for Customer Rebate Programs | E20: 24D | F20: 26B | G20: Wave3 - Complex Pages | H20: 26C | I20: Manage Customer Manual Adjustments (CJM_MANAGE_CUSTOMER_MANUAL_ADJUSTMENTS_PRIV), View Customer Manual Adjustments (CJM_VIEW_CUSTOMER_MANUAL_ADJUSTMENTS_PRIV) | K20: Use the Opt In UI to enable this feature. | L20: OPT IN+Role Setup | N20: Arepally, Susmitha | O20: Customer Programs /Adjustments
A21: 20 | B21: Order Management | C21: Pricing | D21: Redwood: Apply Pricing Promotions According to Pricing Strategies and Payment Terms | E21: 24D | F21: 26B | G21: Wave3 - Complex Pages | H21: 26C | I21: Manage Draft Pricing Promotions (QP_MANAGE_DRAFT_PRICING_PROMOTIONS) Manage Pricing Promotions (QP_MANAGE_PRICING_PROMOTIONS) View Pricing Promotions (QP_VIEW_PRICING_PROMOTIONS) Activate Pricing Promotions (QP_ APPROVE_PRICING_PROMOTIONS) Manage Dynamic Rules (QP_MANAGE_DYNAMIC_RULES) | K21: This is a new feature not available on classic UI | L21: OPT IN | M21: Y | N21: Arepally, Susmitha | O21: Pricing Promotion Work Area
A22: 21 | B22: Order Management | C22: Pricing | D22: Redwood: Copy and Delete Pricing Promotions | E22: 24D | F22: 26B | G22: Wave3 - Complex Pages | H22: 26C | I22: Manage Promotions (QP_MANAGE_PROMOTIONS) | K22: This is a new feature not available on classic UI | L22: OPT IN | M22: Y | N22: Arepally, Susmitha | O22: Pricing Promotion Work Area
A23: 22 | B23: Order Management | C23: Pricing | D23: Redwood: Define Tiered Adjustments on Rate Plan Charges | E23: 24D | F23: 26B | G23: Wave3 - Complex Pages | H23: 26C | I23: Manage Price Lists (QP_MANAGE_PRICE_LISTS) Manage In-Progress Price Lists (QP_MANAGE_IN_PROGRESS_PRICE_LISTS) View Price Lists (QP_VIEW_PRICE_LISTS) Approve Price Lists QP_APPROVE_PRICE_LISTS | K23: This is a new feature not available on classic UI | L23: OPT IN+Role Setup | M23: Y | N23: Arepally, Susmitha | O23: Price List Work Area , New Recurring Charge ,Tier Adjustments
A24: 23 | B24: Order Management | C24: Pricing | D24: Create Pricing Promotions for Sales Orders Using Redwood Pages | E24: 24C | F24: 26A | G24: Wave3 - Complex Pages | H24: 26C | I24: Manage Draft Pricing Promotions (QP_MANAGE_DRAFT_PRICING_PROMOTIONS) Manage Pricing Promotions (QP_MANAGE_PRICING_PROMOTIONS) View Pricing Promotions (QP_VIEW_PRICING_PROMOTIONS) Activate Pricing Promotions (QP_ APPROVE_PRICING_PROMOTIONS) Manage Dynamic Rules (QP_MANAGE_DYNAMIC_RULES) | K24: This is a new feature not available on classic UI | L24: OPT IN+Role Setup | M24: Y | N24: Arepally, Susmitha | O24: Pricing Promotion Work Area
A25: 24 | B25: Order Management | C25: Channel Revenue Management | D25: Add Notes for Customer Programs and Claims in Redwood Pages | E25: 23C | F25: 25B | G25: Wave3 - Complex Pages | H25: 26C | I25: Manage Customer Programs (CJM_MANAGE_CUSTOMER_PROGRAMS_PRIV) Manage Customer Claims (CJM_MANAGE_CUSTOMER_CLAIMS_PRIV) View Only Activity (ZMM_VIEW_ONLY_ACTIVITY_PRIV) | K25: Use the Opt In UI to enable this feature. | L25: OPT IN+Role Setup | N25: Arepally, Susmitha | O25: Customer Program / Claim
A26: 25 | B26: Order Management | C26: Channel Revenue Management | D26: Improve Usability of Claim Pages in Redwood | E26: 23C | F26: 25B | G26: Wave3 - Complex Pages | H26: 26C | I26: Manage Customer Claims (CJM_MANAGE_CUSTOMER_CLAIMS_PRIV) Create Customer Claims (CJM_CREATE_CUSTOMER_CLAIMS_PRIV) View Customer Claims (CJM_VIEW_CUSTOMER_CLAIMS_PRIV) | K26: Use the Opt In UI to enable this feature. | L26: OPT IN+Role Setup | N26: Arepally, Susmitha | O26: Customer Claims Work Area
A27: 26 | B27: Order Management | C27: Channel Revenue Management | D27: Update and Settle Multiple Claims Using Redwood Pages | E27: 23C | F27: 25B | G27: Wave3 - Complex Pages | H27: 26C | I27: Manage Customer Claims (CJM_MANAGE_CUSTOMER_CLAIMS_PRIV) View Only Activity (ZMM_VIEW_ONLY_ACTIVITY_PRIV) | K27: Use the Opt In UI to enable this feature. | L27: OPT IN+Role Setup | N27: Arepally, Susmitha | O27: Customer Claims Work Area
A28: 27 | B28: Order Management | C28: Channel Revenue Management | D28: Manage Deduction Claims Using Redwood Pages | E28: 23B | F28: 26A | G28: Wave3 - Complex Pages | H28: 25C | I28: No additional roles needed to access redwood pages if you already have access to Deductions and Settlement in 23B. Add reference data set access to existing Channel Claim Manager users, in addition to their existing business unit data access. | K28: Use the Opt In UI to enable this feature. | L28: OPT IN+Role Setup | N28: Arepally, Susmitha | O28: Customer Claims Work Area
A29: 28 | B29: Procurement | C29: Sourcing | D29: Redwood: Respond to Simple Negotiations in Supplier Portal | E29: 24D | F29: 26A | G29: Wave1 - Simple Pages | H29: 26B | I29: Create Supplier Negotiation Response (PON_CREATE_SUPPLIER_NEGOTIATION_RESPONSE_PRIV) Edit Supplier Negotiation Response (PON_EDIT_SUPPLIER_NEGOTIATION_RESPONSE_PRIV) | L29: Log Service Request | M29: Y | N29: DESHPANDE, NILESH | O29: Supplier Portal Negotiations Work Area
A30: 29 | B30: Procurement | C30: Sourcing | D30: Redwood: Use Enhanced Negotiation Search in Supplier Portal | E30: 24D | F30: 26A | G30: Wave1 - Simple Pages | H30: 26B | I30: View Supplier Negotiation as Supplier (PON_VIEW_SUPPLIER_NEGOTIATION_SUPPLIER_FACING_PRIV) | L30: OPT IN | M30: Y | N30: DESHPANDE, NILESH | O30: Supplier Portal Negotiations Work Area
A31: 30 | B31: Procurement | C31: Sourcing | D31: Redwood: Use New Buyer Experience for Negotiation Messages | E31: 24D | F31: 25C | G31: Wave1 - Simple Pages | H31: 26B | I31: View Supplier Negotiation Online Message (PON_VIEW_ONLINE_MESSAGE_PRIV) Create Supplier Negotiation Online Message (PON_CREATE_ONLINE_MESSAGE_PRIV) Reply Supplier Negotiation Online Message (PON_REPLY_ONLINE_MESSAGE_PRIV) | L31: OPT IN+ Profile Option | M31: Y | N31: DESHPANDE, NILESH | O31: Negotiation Messages
A32: 31 | B32: Procurement | C32: Sourcing | D32: Redwood: Use New Supplier Experience for Negotiation Messages | E32: 24D | F32: 26A | G32: Wave1 - Simple Pages | H32: 26B | I32: View Supplier Negotiation Online Message as Supplier (PON_VIEW_ONLINE_MESSAGE_SUPPLIER_FACING_PRIV) Create Supplier Negotiation Online Message as Supplier (PON_CREATE_ONLINE_MESSAGE_SUPPLIER_FACING_PRIV) Reply Supplier Negotiation Online Message as Supplier (PON_REPLY_ONLINE_MESSAGE_SUPPLIER_FACING_PRIV) | L32: OPT IN | M32: Y | N32: DESHPANDE, NILESH | O32: Negotiation Messages
A33: 32 | B33: Procurement | C33: Supplier Model | D33: Redwood: Next Generation User Experience for Supplier Registration | E33: 24D | F33: 25C | G33: Wave1 - Simple Pages | H33: 25C | L33: OPT IN | M33: Y | N33: DESHPANDE, NILESH | O33: Supplier Registration UI
A34: 33 | B34: Procurement | C34: Supplier Qualification Management | D34: Redwood: Use Questionnaires in Internal Supplier Registration | E34: 24D | F34: 25C | G34: Wave2 - Modarate Pages | I34: POZ_SUBMIT_SUPPLIER_REGISTRATION_PRIV | K34: Opt in : Redwood: Next Generation User Experience for Supplier Registration | L34: OPT IN+Role Setup | M34: Y | N34: DESHPANDE, NILESH | O34: Supplier Registration UI
A35: 34 | B35: Procurement | C35: Common Procurement | D35: Extend Procurement Redwood Application Pages Using Visual Builder Studio | E35: 24C | F35: 25C | G35: Wave3 - Complex Pages | H35: 25C | L35: Visual Builder | N35: DESHPANDE, NILESH | O35: Visual Builder
A36: 35 | B36: Product Hub | C36: Product Development | D36: Redwood: Secure Manufacturers Using Access Control Lists | E36: 24D | F36: 26A | G36: Wave3 - Complex Pages | H36: 26C | I36: To configure manufacturer conditions using a filtered list: Use REST Service - Identity Integration (ASE_REST_SERVICE_ACCESS_IDENTITY_INTEGRATION_PRIV) Use Atom Feed - Employees Workspace (PER_ATOM_WORKSPACE_ACCESS_EMPLOYEES_PRIV) Manage HCM Lists (HRC_MANAGE_HCM_LISTS_PRIV) Human Capital Management Application Administrator (ORA_HRC_HUMAN_CAPITAL_MANAGEMENT_APPLICATION_ADMINISTRATOR_JOB) To configure teams, permission sets, and conditions: Monitor Product Development (ACA_MONITOR_PRODUCT_DEVELOPMENT_PRIV) Configure Access Control Teams, Permission Sets, and Conditions (EGP_ACCESS_CONTROL_TEAMS_PRIV) Use REST Service - Identity Integration (ASE_REST_SERVICE_ACCESS_IDENTITY_INTEGRATION_PRIV) Use Atom Feed - Employees Workspace (PER_ATOM_WORKSPACE_ACCESS_EMPLOYEES_PRIV) Manage HCM Lists (HRC_MANAGE_HCM_LISTS_PRIV) Manage HCM Rules (HRC_MANAGE_HCM_RULES_PRIV) Run Scheduled Processes (HEY_RUN_SCHEDULED_PROCESSES_PRIV) Manage Scheduled Processes(FND_MANAGE_SCHEDULED_PROCESSES_PRIV) To access the secured manufacturer data: Create Manufacturer (EGP_CREATE_MANUFACTURER_PRIV) View Manufacturers (EGP_VIEW_MANUFACTURER_PRIV) Manage Manufacturers (EGP_MANAGE_MANUFACTURER_PRIV) To access journeys setup and configure the roles in role hierarchy: Manage Journey (ORA_PER_MANAGE_JOURNEY_TEMPLATE) Manage Guided Journeys (ORA_PER_MANAGE_GUIDED_JOURNEYS) Use REST Service - Guided Journeys Read Only (ORA_PER_REST_SERVICE_ACCESS_GUIDED_JOURNEYS_RO) Use REST Service - Journey Categories List of Values (ORA_PER_REST_SERVICE_ACCESS_JOURNEY_CATEGORIES_LOV) To access business rules: Administer Sandbox (FND_ADMINISTER_SANDBOX_PRIV) | K36: Mandate version is not specified hence considering the mandate version as per Roadmap for PLM module which is 26B. | L36: OPT IN | M36: Y | N36: Sujay Parab | O36: Product Management Work Area
A37: 36 | B37: Product Hub | C37: Product Lifecycle Management | D37: Redwood: Create and Manage Personalized Views in Product Management Search | E37: 24D | F37: 26A | G37: Wave1 - Simple Pages | H37: 26C | I37: View Product Management Search (EGP_VIEW_PRODUCT_MGT_SEARCH_PRIV) Get Search View REST (EGP_GET_SEARCH_VIEW_REST_PRIV) GET Product Management Index REST (EGP_GET_PM_INDEX_REST_PRIV) Manage Search View REST (EGP_MANAGE_SEARCH_VIEW_REST_PRIV) | K37: Mandate version is not specified hence considering the mandate version as per Roadmap for PLM module which is 26B. | L37: Role Setup+Profile option | M37: Y | N37: Sujay Parab | O37: Product Information Management Work Area-->Search Products
A38: 37 | B38: Product Hub | C38: Product Lifecycle Management | D38: Redwood: Search Workflow Approvals | E38: 24D | F38: 25C | G38: Wave1 - Simple Pages | H38: 26C | I38: Users with view only access to changes require the following privileges: Access Product Management Change Search (EGO_VIEW_PRODUCT_MANAGEMENT_CHANGE_SEARCH) Get Search View REST (EGP_GET_SEARCH_VIEW_REST_PRIV) GET Product Management Index REST (EGP_GET_PM_INDEX_REST_PRIV) You should have Monitor Product Management Workflow Objects (ACA_MONITOR_PRODUCT_MANAGEMENT_WORFLOW_OBJECTS_PRIV) and one of the following privileges: For change orders: View Change Order (ACA_VIEW_CHANGE_ORDERS_PRIV) or Manage Change Orders (ACA_MANAGE_CHANGE_ORDERS_PRIV) For change requests: View Change Request (ACA_VIEW_CHANGE_REQUESTS_PRIV) Manage Change Requests (ACA_MANAGE_CHANGE_REQUESTS_PRIV) For problem reports: View Problem Report (ACA_VIEW_PROBLEM_REPORTS_PRIV) Manage Problem Report (ACA_MANAGE_PROBLEM_REPORT_PRIV) For corrective and preventive actions: View Corrective Action (ACA_VIEW_CORRECTIVE_ACTIONS_PRIV) Manage Corrective Action (ACA_MANAGE_CORRECTIVE_ACTION_PRIV) To configure the index: Manage Product Management Index (EGP_MANAGE_PM_INDEXES_PRIV) Manage Scheduled Job Definition (FND_MANAGE_SCHEDULED_JOB_DEFINITION_PRIV) Grant Search Framework Manager Permissions (FND_SEARCH_FWK_MGR_PRIV) To rebuild the index: Rebuild Product Management Indexes (EGO_REBUILD_PRODUCT_MGT_INDEXES_PRIV) To create search views: Manage Product Management View (EGP_MANAGE_PM_VIEWS_PRIV) Manage Scheduled Job Definition (FND_MANAGE_SCHEDULED_JOB_DEFINITION_PRIV) Grant Search Framework Manager Permissions (FND_SEARCH_FWK_MGR_PRIV) Access Product Development Configurations Using a REST Service (ACA_GET_PD_CONFIGURATIONS_REST_PRIV) Manage Search View REST (EGP_MANAGE_SEARCH_VIEW_REST_PRIV) Get View Available Attribute REST (EGP_VIEW_AVAIL_ATTR_REST_PRIV) | K38: Mandate version is not specified hence considering the mandate version as per Roadmap for PLM module which is 26B. | L38: Role Setup+Profile option | M38: Y | N38: Sujay Parab | O38: Product Information Management Work Area-->Search Products
A39: 38 | B39: Product Hub | C39: Product Lifecycle Management | D39: Redwood: Search Workflow History | E39: 24D | F39: 25C | G39: Wave1 - Simple Pages | H39: 26C | I39: Users with view only access to changes require the following privileges: Access Product Management Change Search (EGO_VIEW_PRODUCT_MANAGEMENT_CHANGE_SEARCH) View Change History (EGO_VIEW_CHANGE_HISTORY_PRIV) Get Search View REST (EGP_GET_SEARCH_VIEW_REST_PRIV) GET Product Management Index REST (EGP_GET_PM_INDEX_REST_PRIV) You should have Monitor Product Management Workflow Objects (ACA_MONITOR_PRODUCT_MANAGEMENT_WORFLOW_OBJECTS_PRIV) and one of the following privileges: For change orders: View Change Order (ACA_VIEW_CHANGE_ORDERS_PRIV) or Manage Change Orders (ACA_MANAGE_CHANGE_ORDERS_PRIV) For change requests: View Change Request (ACA_VIEW_CHANGE_REQUESTS_PRIV) Manage Change Requests (ACA_MANAGE_CHANGE_REQUESTS_PRIV) For problem reports: View Problem Report (ACA_VIEW_PROBLEM_REPORTS_PRIV) Manage Problem Report (ACA_MANAGE_PROBLEM_REPORT_PRIV) For corrective and preventive actions: View Corrective Action (ACA_VIEW_CORRECTIVE_ACTIONS_PRIV) Manage Corrective Action (ACA_MANAGE_CORRECTIVE_ACTION_PRIV) To configure the index: Manage Product Management Index (EGP_MANAGE_PM_INDEXES_PRIV) Manage Scheduled Job Definition (FND_MANAGE_SCHEDULED_JOB_DEFINITION_PRIV) Grant Search Framework Manager Permissions (FND_SEARCH_FWK_MGR_PRIV) To rebuild the index: Rebuild Product Management Indexes (EGO_REBUILD_PRODUCT_MGT_INDEXES_PRIV) To create search views: Manage Product Management View (EGP_MANAGE_PM_VIEWS_PRIV) Manage Scheduled Job Definition (FND_MANAGE_SCHEDULED_JOB_DEFINITION_PRIV) Grant Search Framework Manager Permissions (FND_SEARCH_FWK_MGR_PRIV) Access Product Development Configurations Using a REST Service (ACA_GET_PD_CONFIGURATIONS_REST_PRIV) Manage Search View REST (EGP_MANAGE_SEARCH_VIEW_REST_PRIV) Get View Available Attribute REST (EGP_VIEW_AVAIL_ATTR_REST_PRIV) | K39: Mandate version is not specified hence considering the mandate version as per Roadmap for PLM module which is 26B. | L39: Role Setup+Profile option | M39: Y | N39: Sujay Parab | O39: Product Information Management Work Area-->Search Products
A40: 39 | B40: Product Hub | C40: Product Development | D40: Create, Edit, and Extend Manufacturers Using a Redwood Page | E40: 24B | F40: 25B | G40: Wave2 - Modarate Pages | H40: 26C | I40: To search for manufacturers using a Redwood page: Get Search View REST(EGP_GET_SEARCH_VIEW_REST_PRIV) To view only manufacturers: View Manufacturer (EGP_VIEW_MANUFACTURER_PRIV) To edit manufacturers: Manage Manufacturer (EGP_MANAGE_MANUFACTURER_PRIV) To create manufacturers: Create Manufacturer (EGP_CREATE_MANUFACTURER_PRIV) Manage Manufacturer (EGP_MANAGE_MANUFACTURER_PRIV) | J40: EGP_MANUFACTURER_REDWOOD_ENABLED | K40: Mandate version is not specified hence considering the mandate version as per Roadmap for PLM module which is 26B. | L40: Role Setup+Profile option | M40: Y | N40: Sujay Parab | O40: Product Development Work Area-->Manufacturers
...

Sheet Pivot
A3: Row Labels | B3: Count of Feature Names
A4: Inventory Management | B4: 290
A5: Maintenance | B5: 100
A6: Manufacturing | B6: 114
A7: Order Management | B7: 110
A8: Procurement | B8: 354
A9: Product Hub | B9: 18
A10: Product Lifecycle Management | B10: 62
A11: Quality Management | B11: 12
A12: SCM Common Components | B12: 21
A13: Supply Chain Collaboration | B13: 20
A14: Supply Chain Orchestration | B14: 18
A15: Supply Chain Planning | B15: 145
... A17: Grand Total | B17: 1295

Sheet Mandate Version
A1: Product | B1: Module | H1: Module | I1: Version
A2: Product Lifecycle Management | B2: Product Management | H2: Supplier Model | I2: 25A
A3: Inventory Management | B3: Cost Management | H3: Cost Management | I3: 25B
A4: Inventory Management | B4: Receipt Accounting | H4: Responsive Self Service Procurement | I4: 25C
A5: Supply Chain Orchestration | B5: Supply Chain Orchestration | H5: Quality Inspection Management | I5: 25D
A6: Inventory Management | B6: Advanced Inventory Management | H6: Manufacturing | I6: 26A
A7: Supply Chain Planning | B7: Sales and Operations Planning | H7: Product Lifecycle Management | I7: 26B
A8: Order Management | B8: Global Order Promising | H8: Service Logistics | I8: 26B
A9: Procurement | B9: Sourcing | H9: Sourcing | I9: 26B
A10: Supply Chain Planning | B10: Replenishment Planning | H10: Purchasing | I10: 26B
A11: SCM Common Components | B11: Configurator | H11: Order Management | I11: 26B
A12: Maintenance | B12: Maintenance | H12: Supply Chain Planning | I12: 26B
... A14: Supply Chain Planning | B14: Demand Management | H14: Maintenance | I14: 26C
A15: SCM Common Components | B15: Global Order Promising | I15: 26D
A16: Manufacturing | B16: Manufacturing | I16: 27A
A17: Inventory Management | B17: Collaboration Messaging Framework
A18: Supply Chain Planning | B18: Supply Planning
A19: Procurement | B19: Collaboration Messaging Framework
A20: Supply Chain Planning | B20: Backlog Management
A21: Supply Chain Planning | B21: Backlog Management
A22: Procurement | B22: Supplier Model
A23: Procurement | B23: Spend Classification
A24: Inventory Management | B24: Inventory Management
A25: Order Management | B25: Order Management
A26: Procurement | B26: External Purchase Prices
A27: Inventory Management | B27: Product Recall Management
A28: Procurement | B28: Purchasing
... A76: Product Lifecycle Management | B76: SCM Common Components

Sheet Overall Sheet
A1: S.no | B1: Product | C1: Module | D1: Feature Names | F1: Update Version | G1: Mandate Version | H1: Wave | I1: CSS Mandate Version | J1: Privilage Name | K1: Profile Options Value | L1: Additional Info | M1: Action Required | N1: Availability of PPT | O1: SME | P1: UI Page Name | Q1: Remarks
A2: 1 | B2: Inventory Management | C2: Mobile Inventory | D2: Redwood: Create an Interorganization Transfer Using a Mobile Device | F2: 24D | G2: 25B | H2: Wave1 - Simple Pages | I2: 26B | J2: Create Interorganization Transfer Using Responsive Inventory Duty (ORA_INV_CREATE_INTERORG_TRANSFER_PWA_DUTY). | M2: Role Setup | N2: Y | O2: Pragyan Dash | P2: Inventory Management (Mobile)
A3: 2 | B3: Inventory Management | C3: Mobile Inventory | D3: Redwood: View the Inventory Management (New) Tile as Inventory Management (Mobile) | F3: 24D | G3: 25B | H3: Wave1 - Simple Pages | I3: 26B | M3: Auto Enabled | P3: Inventory Management (Mobile)
A4: 3 | B4: Inventory Management | C4: Mobile Inventory | D4: Redwood: Inspect Received Goods Using a Mobile Device | F4: 24D | G4: 25B | H4: Wave1 - Simple Pages | I4: 26B | J4: New: Inspect goods using the responsive receiving application (ORA_RCV_INSPECT_GOODS_PWA_DUTY) | K4: Manage Inventory Profile Options > ORA_INV_MOBILE_INVENTORY_MANAGEMENT_REDWOOD_ENABLED = Yes | L4: 1. Activate Sandbox to enable the Inventory Management (New) 2. Run the "ESS job to create index definition and perform Initial Ingest to OSCS" Refer: https://docs.oracle.com/en/cloud/saas/readiness/scm/24b/inv24b/24B-inventory-wn-f31373.htm | M4: Profile Option | P4: Inventory Management (Mobile)
A5: 4 | B5: Inventory Management | C5: Mobile Inventory | D5: Redwood: View Lot Attributes in Mobile Inventory Transactions | F5: 24D | G5: 25B | H5: Wave1 - Simple Pages | I5: 26B | M5: Auto Enabled | P5: Inventory Management (Mobile)
A6: 5 | B6: Inventory Management | C6: Cost Management | D6: Redwood: View Rollup Costs Using a New User Experience | F6: 25A | G6: 25B | H6: Wave1 - Simple Pages | I6: 26A | J6: Users who are assigned a configured job role that contains the following privilege can access this feature: View Rolled Up Costs (CST_REVIEW_ROLLEDUP_COSTS) | K6: On the Manage Administrator Profile Values page, search for and select the ORA_CST_VIEW_ROLLEDUP_COSTS_REDWOOD_ENABLED profile option code. In the Profile Values section, set the Site level to Yes. The default value is No. Click Save and Close. Changes in the profile value will affect users the next time they sign in. Yes = enables the feature No = disables the feature | M6: Role Setup+Profile option | N6: Y | O6: Miriam Chandni | P6: Cost Accounting Work Area
A7: 6 | B7: Inventory Management | C7: Cost Management | D7: Redwood: Create and Update Cost Scenarios Using a New User Experience | F7: 25A | G7: 25B | H7: Wave2 - Modarate Pages | I7: 26A | J7: Users who are assigned a configured job role that contains the following privilege can access this feature: Manage Cost Planning Scenario Definition (CST_MANAGE_SCENARIO) | K7: On the Manage Administrator Profile Values page, search for and select the ORA_CST_PLANNING_SCENARIOS_REDWOOD_ENABLED profile option code. In the Profile Values section, set the Site level to Yes. The default value is No. Click Save and Close. Changes in the profile value will affect users the next time they sign in. Yes = enables the feature No = disables the feature | M7: Role Setup+Profile option | N7: Y | O7: Miriam Chandni | P7: Cost Accounting Work Area
A8: 7 | B8: Inventory Management | C8: Cost Management | D8: Redwood: Review Standard Costs Import Exceptions Using a New User Experience | F8: 25A | G8: 25B | H8: Wave1 - Simple Pages | I8: 26A | J8: Users who are assigned a configured job role that contains the following privilege can access this feature: Estimate Costs (CST_ESTIMATE_COSTS) | K8: On the Manage Administrator Profile Values page, search for and select the ORA_CST_STD_COST_IMPORT_EXCEPTIONS_REDWOOD_ENABLED profile option code. In the Profile Values section, set the Site level to Yes. The default value is No. Click Save and Close. Changes in the profile value will affect users the next time they sign in. Yes = enables the feature No = disables the feature | M8: Role Setup+Profile option | N8: Y | O8: Miriam Chandni | P8: Cost Accounting Work Area
A9: 8 | B9: Inventory Management | C9: Receiving | D9: Redwood: Manage Inbound Shipments and Create ASN or ASBN Using a Redwood Page | F9: 24D | G9: 25C | H9: Wave1 - Simple Pages | I9: 26A | J9: 1. Manage Inbound Shipment Using Responsive Receiving (RCV_MANAGE_INBOUND_SHIPMENT_PWA) 2. Manage Inbound Shipment as Supplier Using Responsive Receiving (RCV_MANAGE_INBOUND_SHIPMENT_AS_SUPPLIER_PWA) 3. Create Advance Shipment Notice Using Responsive Receiving (RCV_CREATE_ADVANCE_SHIPMENT_NOTICE_PWA) 4. Create Advance Shipment Notice as Supplier Using Responsive Receiving (RCV_CREATE_ADVANCE_SHIPMENT_NOTICE_AS_SUPPLIER_PWA) | K9: Manage Receiving Profile Options > 1. ORA_RCV_INBOUND_SHIPMENTS_REDWOOD_ENABLED = Yes 2. ORA_RCV_ADVANCE_SHIPMENT_NOTICE_REDWOOD_ENABLED = Yes 3. ORA_RCV_INBOUND_SHIPMENTS_SUPPLIER_PORTAL_REDWOOD_ENABLED = Yes 4. ORA_RCV_ADVANCE_SHIPMENT_NOTICE_SUPPLIER_PORTAL_REDWOOD_ENABLED = Yes | L9: 1. Activate Sandbox to enable the Inventory Management (New) 2. Run the "ESS job to create index definition and perform Initial Ingest to OSCS" Refer: https://docs.oracle.com/en/cloud/saas/readiness/scm/24b/inv24b/24B-inventory-wn-f31373.htm | M9: Profile Option | N9: Y | O9: Mukesh Panwar | P9: Receipts
A10: 9 | B10: Inventory Management | C10: Receiving | D10: Redwood: View Receipts and Receipt Returns in Supplier Portal Using a Redwood Page | F10: 24D | G10: 25C | H10: Wave1 - Simple Pages | I10: 26A | J10: View Receiving Receipt and Receipt Return as Supplier (RCV_VIEW_RECEIVING_RECEIPT_AND_RECEIPT_RETURN_AS_SUPPLIER_PRIV) | K10: Manage Receiving Profile Options task > ORA_RCV_RECEIPTS_RETURNS_SUPPLIER_PORTAL_REDWOOD_ENABLED = Yes | M10: Profile Option | N10: Y | O10: Pragyan Dash | P10: Supplier Portal
A11: 10 | B11: Inventory Management | C11: Cost Management | D11: Create and Edit Overhead Rates Using Redwood Pages | F11: 24C | G11: 26B | H11: Wave2 - Modarate Pages | I11: 26A | J11: Users who are assigned a configured job role that contains the following privilege can access this feature: Manage Resource and Overhead Rate Plans (CST_MANAGE_RATE_PLANS) | K11: On the Manage Administrator Profile Values page, search for and select the ORA_CST_RESOURCE_RATES_REDWOOD_ENABLED profile option code. In the Profile Values section, set the Site level to Yes. The default value is No. Yes = enables the feature No = disables the feature | L11: Part of the standard setups | M11: Role Setup+Profile option | O11: Rekha Bhoopathy | P11: Overhead Rates
A12: 11 | B12: Inventory Management | C12: Fiscal Document Capture | D12: Manage Tolerances Using the Redwood Experience | F12: 24C | G12: 26B | H12: Wave2 - Modarate Pages | I12: 26B | J12: Set Up Fiscal Document Tolerances (CMF_FISCAL_DOC_TOLERANCES) Manage Fiscal Document Tolerances by Web Service (CMF_FISCAL_DOC_TOLERANCE_WEB_SERVICE) | K12: On the Manage Administrator Profile Values page, enable the new ORA_CMF_TOLERANCE_RULES_REDWOOD_ENABLED profile option at Site or Product or User level. Select Yes for the Redwood page for Fiscal Document Tolerance Rules Enabled option. | L12: Part of the standard setups | M12: Role Setup+Profile option | O12: Rekha Boopathy | P12: Fiscal Document Tolerance Rules
A13: 12 | B13: Supply Chain Orchestration | C13: Supply Chain Orchestration | D13: Manage Documentation and Accounting Rule in Redwood Pages | F13: 24C | G13: 26B | H13: Wave1 - Simple Pages | I13: 26D | J13: Maintain Documentation and Accounting Rules (FOS_MAINTAIN_TRADE_AND_ACCOUNTING_RULES) Manage Documentation and Accounting Rules (FOS_MANAGE_TRADE_AND_ACCOUNTING_RULES) View Documentation and Accounting Rules (FOS_VIEW_TRADE_AND_ACCOUNTING_RULES) | K13: ORA_FOS_TRADE_ACCOUNTING_RULES_REDWOOD_ENABLED | M13: Role Setup+Profile option | N13: Y | O13: Veeranarayana Swamy | P13: Documentation and Accounting Rules
A14: 13 | B14: Supply Chain Orchestration | C14: Supply Chain Orchestration | D14: Manage Transfer Pricing Rule in Redwood Pages | F14: 24C | G14: 26B | H14: Wave1 - Simple Pages | I14: 26D | J14: Maintain Transfer Pricing Rules (FOS_MAINTAIN_TRANSFER_PRICING_RULES) Manage Transfer Pricing Rules (FOS_MANAGE_TRANSFER_PRICING_RULES) View Transfer Pricing Rules (FOS_VIEW_TRANSFER_PRICING_RULES) | K14: ORA_FOS_TRANSFER_PRICING_RULES_REDWOOD_ENABLED | M14: Role Setup+Profile option | N14: Y | O14: Miriam Chandni | P14: Financial Orchestration Work Area
A15: 14 | B15: Inventory Management | C15: Cost Management | D15: Create and Update Resource Rates Using Redwood Pages | F15: 24B | G15: 26B | H15: Wave2 - Modarate Pages | I15: 26A | J15: Users who are assigned a configured job role that contains the following privilege can access this feature: Manage Resource and Overhead Rate Plans (CST_MANAGE_RATE_PLANS) | K15: On the Manage Administrator Profile Values page, search for and select the ORA_CST_RESOURCE_RATES_REDWOOD_ENABLED profile option code. In the Profile Values section, set the Site level to Yes. The default value is No. Yes = enables the feature No = disables the feature | L15: Part of the standard setups | M15: Role Setup+Profile option | O15: Rekha Bhoopathy | P15: Resource Rates
A16: 15 | B16: Inventory Management | C16: Cost Management | D16: Redwood: View Scenario Exceptions Using a New User Experience | F16: 25A | G16: 25B | H16: Wave1 - Simple Pages | I16: 26A | J16: Users who are assigned a configured job role that contains the following privilege can access this feature: View Scenario Exceptions (CST_MANAGE_SCENRIO_EXCEPTIONS) | K16: On the Manage Administrator Profile Values page, search for and select the ORA_CST_SCENARIO_EXCEPTIONS_REDWOOD_ENABLED profile option code. In the Profile Values section, set the Site level to Yes. The default value is No. Click Save and Close. Changes in the profile value will affect users the next time they sign in. Yes = enables the feature No = disables the feature | M16: Role Setup+Profile option | N16: Y | O16: Miriam Chandni | P16: Cost Accounting Work Area
A17: 16 | B17: Manufacturing | C17: Manufacturing | D17: Search for, Create, and Edit a Standard Item Work Definition Using the Redwood User Experience | F17: 24B | G17: 26B | H17: Wave1 - Simple Pages | I17: 26A | K17: ORA_WIS_WORK_DEFINITIONS_REDWOOD_ENABLED | M17: Role Setup+Profile option | N17: Y | O17: Yoga Gopalakrishnan | P17: Manage Work Definitions Page
A18: 17 | B18: Order Management | C18: Channel Revenue Management | D18: Redwood: Define Product Eligibility Based on Item Categories for Customer Rebate Programs | F18: 24D | G18: 25A | H18: Wave3 - Complex Pages | I18: 26C | J18: Manage Customer Programs (CJM_MANAGE_CUSTOMER_PROGRAMS_PRIV) | L18: Use the Opt In UI to enable this feature. | M18: OPT IN+Role Setup | O18: TBD | P18: Customer Rebate Work Area
A19: 18 | B19: Order Management | C19: Channel Revenue Management | D19: Redwood: Exclude Multiple Items or Item Categories in Product Eligibility Rules | F19: 24D | G19: 25C | H19: Wave3 - Complex Pages | I19: 26C | J19: Manage Customer Programs (CJM_MANAGE_CUSTOMER_PROGRAMS_PRIV) | L19: Use the Opt In UI to enable this feature. | M19: OPT IN+Role Setup | O19: TBD | P19: Customer Rebate Work Area
A20: 19 | B20: Order Management | C20: Channel Revenue Management | D20: Redwood: Manage Manual Accrual Adjustments for Customer Rebate Programs | F20: 24D | G20: 26B | H20: Wave3 - Complex Pages | I20: 26C | J20: Manage Customer Manual Adjustments (CJM_MANAGE_CUSTOMER_MANUAL_ADJUSTMENTS_PRIV), View Customer Manual Adjustments (CJM_VIEW_CUSTOMER_MANUAL_ADJUSTMENTS_PRIV) | L20: Use the Opt In UI to enable this feature. | M20: OPT IN+Role Setup | O20: TBD | P20: Customer Rebate Work Area
A21: 20 | B21: Order Management | C21: Pricing | D21: Redwood: Apply Pricing Promotions According to Pricing Strategies and Payment Terms | F21: 24D | G21: 26B | H21: Wave3 - Complex Pages | I21: 26C | J21: Manage Draft Pricing Promotions (QP_MANAGE_DRAFT_PRICING_PROMOTIONS) Manage Pricing Promotions (QP_MANAGE_PRICING_PROMOTIONS) View Pricing Promotions (QP_VIEW_PRICING_PROMOTIONS) Activate Pricing Promotions (QP_ APPROVE_PRICING_PROMOTIONS) Manage Dynamic Rules (QP_MANAGE_DYNAMIC_RULES) | L21: This is a new feature not available on classic UI | M21: OPT IN | N21: Y | O21: Mukesh Panwar | P21: Pricing Promotions
A22: 21 | B22: Order Management | C22: Pricing | D22: Redwood: Copy and Delete Pricing Promotions | F22: 24D | G22: 26B | H22: Wave3 - Complex Pages | I22: 26C | J22: Manage Promotions (QP_MANAGE_PROMOTIONS) | L22: This is a new feature not available on classic UI | M22: OPT IN | N22: Y | O22: Mukesh Panwar | P22: Pricing Promotions
A23: 22 | B23: Order Management | C23: Pricing | D23: Redwood: Define Tiered Adjustments on Rate Plan Charges | F23: 24D | G23: 26B | H23: Wave3 - Complex Pages | I23: 26C | J23: Manage Price Lists (QP_MANAGE_PRICE_LISTS) Manage In-Progress Price Lists (QP_MANAGE_IN_PROGRESS_PRICE_LISTS) View Price Lists (QP_VIEW_PRICE_LISTS) Approve Price Lists QP_APPROVE_PRICE_LISTS | L23: This is a new feature not available on classic UI | M23: OPT IN+Role Setup | N23: Y | O23: Mukesh Panwar | P23: Price List
A24: 23 | B24: Order Management | C24: Pricing | D24: Create Pricing Promotions for Sales Orders Using Redwood Pages | F24: 24C | G24: 26A | H24: Wave3 - Complex Pages | I24: 26C | J24: Manage Draft Pricing Promotions (QP_MANAGE_DRAFT_PRICING_PROMOTIONS) Manage Pricing Promotions (QP_MANAGE_PRICING_PROMOTIONS) View Pricing Promotions (QP_VIEW_PRICING_PROMOTIONS) Activate Pricing Promotions (QP_ APPROVE_PRICING_PROMOTIONS) Manage Dynamic Rules (QP_MANAGE_DYNAMIC_RULES) | L24: This is a new feature not available on classic UI | M24: OPT IN+Role Setup | N24: Y | O24: Mukesh Panwar | P24: Pricing Promotions
A25: 24 | B25: Order Management | C25: Channel Revenue Management | D25: Add Notes for Customer Programs and Claims in Redwood Pages | F25: 23C | G25: 25B | H25: Wave3 - Complex Pages | I25: 26C | J25: Manage Customer Programs (CJM_MANAGE_CUSTOMER_PROGRAMS_PRIV) Manage Customer Claims (CJM_MANAGE_CUSTOMER_CLAIMS_PRIV) View Only Activity (ZMM_VIEW_ONLY_ACTIVITY_PRIV) | L25: Use the Opt In UI to enable this feature. | M25: OPT IN+Role Setup | O25: TBD | P25: Customer Rebate Work Area
A26: 25 | B26: Order Management | C26: Channel Revenue Management | D26: Improve Usability of Claim Pages in Redwood | F26: 23C | G26: 25B | H26: Wave3 - Complex Pages | I26: 26C | J26: Manage Customer Claims (CJM_MANAGE_CUSTOMER_CLAIMS_PRIV) Create Customer Claims (CJM_CREATE_CUSTOMER_CLAIMS_PRIV) View Customer Claims (CJM_VIEW_CUSTOMER_CLAIMS_PRIV) | L26: Use the Opt In UI to enable this feature. | M26: OPT IN+Role Setup | O26: TBD | P26: Customer Claims Work Area
A27: 26 | B27: Order Management | C27: Channel Revenue Management | D27: Update and Settle Multiple Claims Using Redwood Pages | F27: 23C | G27: 25B | H27: Wave3 - Complex Pages | I27: 26C | J27: Manage Customer Claims (CJM_MANAGE_CUSTOMER_CLAIMS_PRIV) View Only Activity (ZMM_VIEW_ONLY_ACTIVITY_PRIV) | L27: Use the Opt In UI to enable this feature. | M27: OPT IN+Role Setup | O27: TBD | P27: Customer Claims Work Area
A28: 27 | B28: Order Management | C28: Channel Revenue Management | D28: Manage Deduction Claims Using Redwood Pages | F28: 23B | G28: 26A | H28: Wave3 - Complex Pages | I28: 25C | J28: No additional roles needed to access redwood pages if you already have access to Deductions and Settlement in 23B. Add reference data set access to existing Channel Claim Manager users, in addition to their existing business unit data access. | L28: Use the Opt In UI to enable this feature. | M28: OPT IN+Role Setup | O28: TBD | P28: Customer Claims Work Area
A29: 28 | B29: Procurement | C29: Sourcing | D29: Redwood: Respond to Simple Negotiations in Supplier Portal | F29: 24D | G29: 26A | H29: Wave1 - Simple Pages | I29: 26B | J29: Create Supplier Negotiation Response (PON_CREATE_SUPPLIER_NEGOTIATION_RESPONSE_PRIV) Edit Supplier Negotiation Response (PON_EDIT_SUPPLIER_NEGOTIATION_RESPONSE_PRIV) | M29: Log Service Request | N29: Y | O29: Karthik Gopal | P29: Requirements
A30: 29 | B30: Procurement | C30: Sourcing | D30: Redwood: Use Enhanced Negotiation Search in Supplier Portal | F30: 24D | G30: 26A | H30: Wave1 - Simple Pages | I30: 26B | J30: View Supplier Negotiation as Supplier (PON_VIEW_SUPPLIER_NEGOTIATION_SUPPLIER_FACING_PRIV) | M30: OPT IN | N30: Y | O30: Ashoka Veerabhadrappa | P30: negotiation in supplier portal
A31: 30 | B31: Procurement | C31: Sourcing | D31: Redwood: Use New Buyer Experience for Negotiation Messages | F31: 24D | G31: 25C | H31: Wave1 - Simple Pages | I31: 26B | J31: View Supplier Negotiation Online Message (PON_VIEW_ONLINE_MESSAGE_PRIV) Create Supplier Negotiation Online Message (PON_CREATE_ONLINE_MESSAGE_PRIV) Reply Supplier Negotiation Online Message (PON_REPLY_ONLINE_MESSAGE_PRIV) | M31: OPT IN+ Profile Option | N31: Y | O31: Ashoka Veerabhadrappa | P31: negotiation Messages
A32: 31 | B32: Procurement | C32: Sourcing | D32: Redwood: Use New Supplier Experience for Negotiation Messages | F32: 24D | G32: 26A | H32: Wave1 - Simple Pages | I32: 26B | J32: View Supplier Negotiation Online Message as Supplier (PON_VIEW_ONLINE_MESSAGE_SUPPLIER_FACING_PRIV) Create Supplier Negotiation Online Message as Supplier (PON_CREATE_ONLINE_MESSAGE_SUPPLIER_FACING_PRIV) Reply Supplier Negotiation Online Message as Supplier (PON_REPLY_ONLINE_MESSAGE_SUPPLIER_FACING_PRIV) | M32: OPT IN | N32: Y | O32: Ashoka Veerabhadrappa | P32: negotiation Messages
A33: 32 | B33: Procurement | C33: Supplier Model | D33: Redwood: Next Generation User Experience for Supplier Registration | F33: 24D | G33: 25C | H33: Wave1 - Simple Pages | I33: 25C | M33: OPT IN | N33: Y | O33: Ashoka Veerabhadrappa | P33: Supplier Registration UI
A34: 33 | B34: Procurement | C34: Supplier Qualification Management | D34: Redwood: Use Questionnaires in Internal Supplier Registration | F34: 24D | G34: 25C | H34: Wave2 - Modarate Pages | J34: POZ_SUBMIT_SUPPLIER_REGISTRATION_PRIV | L34: Opt in : Redwood: Next Generation User Experience for Supplier Registration | M34: OPT IN+Role Setup | N34: Y | O34: Ashoka Veerabhadrappa | P34: Supplier Registration UI
A35: 34 | B35: Procurement | C35: Common Procurement | D35: Extend Procurement Redwood Application Pages Using Visual Builder Studio | F35: 24C | G35: 25C | H35: Wave3 - Complex Pages | I35: 25C | M35: Visual Builder | O35: Pravalika G | P35: Vishual Builder | R35: Manufacturing and Product Life Cylce Management
A36: 35 | B36: Product Hub | C36: Product Development | D36: Redwood: Secure Manufacturers Using Access Control Lists | F36: 24D | G36: 26A | H36: Wave3 - Complex Pages | I36: 26C | J36: To configure manufacturer conditions using a filtered list: Use REST Service - Identity Integration (ASE_REST_SERVICE_ACCESS_IDENTITY_INTEGRATION_PRIV) Use Atom Feed - Employees Workspace (PER_ATOM_WORKSPACE_ACCESS_EMPLOYEES_PRIV) Manage HCM Lists (HRC_MANAGE_HCM_LISTS_PRIV) Human Capital Management Application Administrator (ORA_HRC_HUMAN_CAPITAL_MANAGEMENT_APPLICATION_ADMINISTRATOR_JOB) To configure teams, permission sets, and conditions: Monitor Product Development (ACA_MONITOR_PRODUCT_DEVELOPMENT_PRIV) Configure Access Control Teams, Permission Sets, and Conditions (EGP_ACCESS_CONTROL_TEAMS_PRIV) Use REST Service - Identity Integration (ASE_REST_SERVICE_ACCESS_IDENTITY_INTEGRATION_PRIV) Use Atom Feed - Employees Workspace (PER_ATOM_WORKSPACE_ACCESS_EMPLOYEES_PRIV) Manage HCM Lists (HRC_MANAGE_HCM_LISTS_PRIV) Manage HCM Rules (HRC_MANAGE_HCM_RULES_PRIV) Run Scheduled Processes (HEY_RUN_SCHEDULED_PROCESSES_PRIV) Manage Scheduled Processes(FND_MANAGE_SCHEDULED_PROCESSES_PRIV) To access the secured manufacturer data: Create Manufacturer (EGP_CREATE_MANUFACTURER_PRIV) View Manufacturers (EGP_VIEW_MANUFACTURER_PRIV) Manage Manufacturers (EGP_MANAGE_MANUFACTURER_PRIV) To access journeys setup and configure the roles in role hierarchy: Manage Journey (ORA_PER_MANAGE_JOURNEY_TEMPLATE) Manage Guided Journeys (ORA_PER_MANAGE_GUIDED_JOURNEYS) Use REST Service - Guided Journeys Read Only (ORA_PER_REST_SERVICE_ACCESS_GUIDED_JOURNEYS_RO) Use REST Service - Journey Categories List of Values (ORA_PER_REST_SERVICE_ACCESS_JOURNEY_CATEGORIES_LOV) To access business rules: Administer Sandbox (FND_ADMINISTER_SANDBOX_PRIV) | L36: Mandate version is not specified hence considering the mandate version as per Roadmap for PLM module which is 26B. | M36: OPT IN | N36: Y | O36: Miriam Chandni | P36: Product Management Work Area
A37: 36 | B37: Product Hub | C37: Product Lifecycle Management | D37: Redwood: Create and Manage Personalized Views in Product Management Search | F37: 24D | G37: 26A | H37: Wave1 - Simple Pages | I37: 26C | J37: View Product Management Search (EGP_VIEW_PRODUCT_MGT_SEARCH_PRIV) Get Search View REST (EGP_GET_SEARCH_VIEW_REST_PRIV) GET Product Management Index REST (EGP_GET_PM_INDEX_REST_PRIV) Manage Search View REST (EGP_MANAGE_SEARCH_VIEW_REST_PRIV) | L37: Mandate version is not specified hence considering the mandate version as per Roadmap for PLM module which is 26B. | M37: Role Setup+Profile option | N37: Y | O37: Miriam Chandni | P37: Product Information Management Work Area
A38: 37 | B38: Product Hub | C38: Product Lifecycle Management | D38: Redwood: Search Workflow Approvals | F38: 24D | G38: 25C | H38: Wave1 - Simple Pages | I38: 26C | J38: Users with view only access to changes require the following privileges: Access Product Management Change Search (EGO_VIEW_PRODUCT_MANAGEMENT_CHANGE_SEARCH) Get Search View REST (EGP_GET_SEARCH_VIEW_REST_PRIV) GET Product Management Index REST (EGP_GET_PM_INDEX_REST_PRIV) You should have Monitor Product Management Workflow Objects (ACA_MONITOR_PRODUCT_MANAGEMENT_WORFLOW_OBJECTS_PRIV) and one of the following privileges: For change orders: View Change Order (ACA_VIEW_CHANGE_ORDERS_PRIV) or Manage Change Orders (ACA_MANAGE_CHANGE_ORDERS_PRIV) For change requests: View Change Request (ACA_VIEW_CHANGE_REQUESTS_PRIV) Manage Change Requests (ACA_MANAGE_CHANGE_REQUESTS_PRIV) For problem reports: View Problem Report (ACA_VIEW_PROBLEM_REPORTS_PRIV) Manage Problem Report (ACA_MANAGE_PROBLEM_REPORT_PRIV) For corrective and preventive actions: View Corrective Action (ACA_VIEW_CORRECTIVE_ACTIONS_PRIV) Manage Corrective Action (ACA_MANAGE_CORRECTIVE_ACTION_PRIV) To configure the index: Manage Product Management Index (EGP_MANAGE_PM_INDEXES_PRIV) Manage Scheduled Job Definition (FND_MANAGE_SCHEDULED_JOB_DEFINITION_PRIV) Grant Search Framework Manager Permissions (FND_SEARCH_FWK_MGR_PRIV) To rebuild the index: Rebuild Product Management Indexes (EGO_REBUILD_PRODUCT_MGT_INDEXES_PRIV) To create search views: Manage Product Management View (EGP_MANAGE_PM_VIEWS_PRIV) Manage Scheduled Job Definition (FND_MANAGE_SCHEDULED_JOB_DEFINITION_PRIV) Grant Search Framework Manager Permissions (FND_SEARCH_FWK_MGR_PRIV) Access Product Development Configurations Using a REST Service (ACA_GET_PD_CONFIGURATIONS_REST_PRIV) Manage Search View REST (EGP_MANAGE_SEARCH_VIEW_REST_PRIV) Get View Available Attribute REST (EGP_VIEW_AVAIL_ATTR_REST_PRIV) | L38: Mandate version is not specified hence considering the mandate version as per Roadmap for PLM module which is 26B. | M38: Role Setup+Profile option | N38: Y | O38: Miriam Chandni | P38: Product Management Experience
